Workbook

Sheet Curve
A1: Case Temp(℃) | B1: WL@Operational current_1270 | C1: WL@Operational current_1290 | D1: WL@Operational current_1310 | E1: WL@Operational current_1330 | G1: Case Temp(℃) | H1: WL@Maximum current_@1270 | I1: WL@Maximum current_@1290 | J1: WL@Maximum current_1310 | K1: WL@Maximum current_1330 | V1: =A1 -> Case Temp(℃) | W1: Operational_TxP_1270 | X1: Operational_TxP_1290 | Y1: Operational_TxP_1310 | Z1: Operational_TxP_1330 | AA1: Operational_DDMI Bias_1270 | AB1: Operational_DDMI Bias_1290 | AC1: Operational_DDMI Bias_1310 | AD1: Operational_DDMI Bias_1330 | AE1: =Maximum!Q1 -> Case Temp(℃) | AF1: Max_DDMI Bias | AG1: Max_TxP_1270 | AH1: Max_TxP_1290 | AI1: Max_TxP_1310 | AJ1: Max_TxP_1330 | AK1: CH1_N | AL1: CH2_N | AM1: CH3_N | AN1: CH4_N | AO1: CH1_M | AP1: CH2_M | AQ1: CH3_M | AR1: CH4_M
A2: =Operational!Q2 -> -0.21 | B2: =Operational!R2 -> 1267.809 | C2: =Operational!S2 -> 1287.61 | D2: =Operational!T2 -> 1308.322 | E2: =Operational!U2 -> 1327.604 | G2: =Maximum!Q2 -> 70.77 | H2: =Maximum!R2 -> 1275.393 | I2: =Maximum!S2 -> 1295.377 | J2: =Maximum!T2 -> 1315.948 | K2: =Maximum!U2 -> 1335.366 | V2: =A2 -> -0.21 | W2: =Operational!V2 -> 1.4 | X2: =Operational!W2 -> 0.9 | Y2: =Operational!X2 -> 2.49 | Z2: =Operational!Y2 -> 2.17 | AA2: =Operational!AD2 -> 124 | AB2: =Operational!AE2 -> 140 | AC2: =Operational!AF2 -> 124 | AD2: =Operational!AG2 -> 140 | AE2: =Maximum!Q2 -> 70.77 | AF2: =Maximum!AD2 -> 399 | AG2: =Maximum!V2 -> 2.83 | AH2: =Maximum!W2 -> 2.57 | AI2: =Maximum!X2 -> 3.98 | AJ2: =Maximum!Y2 -> 2.9
A3: =Operational!Q3 -> 0.75 | B3: =Operational!R3 -> 1267.892 | C3: =Operational!S3 -> 1287.694 | D3: =Operational!T3 -> 1308.407 | E3: =Operational!U3 -> 1327.69 | G3: =Maximum!Q3 -> 69.81 | H3: =Maximum!R3 -> 1275.306 | I3: =Maximum!S3 -> 1295.29 | J3: =Maximum!T3 -> 1315.863 | K3: =Maximum!U3 -> 1335.279 | V3: =A3 -> 0.75 | W3: =Operational!V3 -> 1.29 | X3: =Operational!W3 -> 0.86 | Y3: =Operational!X3 -> 2.49 | Z3: =Operational!Y3 -> 2.11 | AA3: =Operational!AD3 -> 124 | AB3: =Operational!AE3 -> 140 | AC3: =Operational!AF3 -> 124 | AD3: =Operational!AG3 -> 140 | AE3: =Maximum!Q3 -> 69.81 | AF3: =Maximum!AD3 -> 399 | AG3: =Maximum!V3 -> 3.08 | AH3: =Maximum!W3 -> 2.74 | AI3: =Maximum!X3 -> 4.14 | AJ3: =Maximum!Y3 -> 3 | AK3: =W2-W3 -> 0.11 | AL3: =X2-X3 -> 0.04 | AM3: =Y2-Y3 -> 0 | AN3: =Z2-Z3 -> 0.06 | AO3: =AG2-AG3 -> -0.25 | AP3: =AH2-AH3 -> -0.17 | AQ3: =AI2-AI3 -> -0.16 | AR3: =AJ2-AJ3 -> -0.1
A4: =Operational!Q4 -> 1.76 | B4: =Operational!R4 -> 1267.976 | C4: =Operational!S4 -> 1287.78 | D4: =Operational!T4 -> 1308.495 | E4: =Operational!U4 -> 1327.778 | G4: =Maximum!Q4 -> 69 | H4: =Maximum!R4 -> 1275.219 | I4: =Maximum!S4 -> 1295.202 | J4: =Maximum!T4 -> 1315.775 | K4: =Maximum!U4 -> 1335.193 | V4: =A4 -> 1.76 | W4: =Operational!V4 -> 1.31 | X4: =Operational!W4 -> 0.89 | Y4: =Operational!X4 -> 2.41 | Z4: =Operational!Y4 -> 2.08 | AA4: =Operational!AD4 -> 125 | AB4: =Operational!AE4 -> 140 | AC4: =Operational!AF4 -> 125 | AD4: =Operational!AG4 -> 140 | AE4: =Maximum!Q4 -> 69 | AF4: =Maximum!AD4 -> 399 | AG4: =Maximum!V4 -> 3.26 | AH4: =Maximum!W4 -> 2.86 | AI4: =Maximum!X4 -> 4.28 | AJ4: =Maximum!Y4 -> 3.1 | AK4: =W3-W4 -> -0.02 | AL4: =X3-X4 -> -0.03 | AM4: =Y3-Y4 -> 0.08 | AN4: =Z3-Z4 -> 0.03 | AO4: =AG3-AG4 -> -0.18 | AP4: =AH3-AH4 -> -0.12 | AQ4: =AI3-AI4 -> -0.14 | AR4: =AJ3-AJ4 -> -0.1
A5: =Operational!Q5 -> 2.7 | B5: =Operational!R5 -> 1268.061 | C5: =Operational!S5 -> 1287.868 | D5: =Operational!T5 -> 1308.583 | E5: =Operational!U5 -> 1327.866 | G5: =Maximum!Q5 -> 68.02 | H5: =Maximum!R5 -> 1275.131 | I5: =Maximum!S5 -> 1295.112 | J5: =Maximum!T5 -> 1315.687 | K5: =Maximum!U5 -> 1335.104 | V5: =A5 -> 2.7 | W5: =Operational!V5 -> 1.36 | X5: =Operational!W5 -> 0.94 | Y5: =Operational!X5 -> 2.46 | Z5: =Operational!Y5 -> 2.09 | AA5: =Operational!AD5 -> 126 | AB5: =Operational!AE5 -> 140 | AC5: =Operational!AF5 -> 126 | AD5: =Operational!AG5 -> 140 | AE5: =Maximum!Q5 -> 68.02 | AF5: =Maximum!AD5 -> 399 | AG5: =Maximum!V5 -> 3.47 | AH5: =Maximum!W5 -> 3.06 | AI5: =Maximum!X5 -> 4.38 | AJ5: =Maximum!Y5 -> 3.23 | AK5: =W4-W5 -> -0.05 | AL5: =X4-X5 -> -0.05 | AM5: =Y4-Y5 -> -0.05 | AN5: =Z4-Z5 -> -0.01 | AO5: =AG4-AG5 -> -0.21 | AP5: =AH4-AH5 -> -0.2 | AQ5: =AI4-AI5 -> -0.1 | AR5: =AJ4-AJ5 -> -0.13
A6: =Operational!Q6 -> 3.69 | B6: =Operational!R6 -> 1268.148 | C6: =Operational!S6 -> 1287.957 | D6: =Operational!T6 -> 1308.671 | E6: =Operational!U6 -> 1327.956 | G6: =Maximum!Q6 -> 67.13 | H6: =Maximum!R6 -> 1275.042 | I6: =Maximum!S6 -> 1295.022 | J6: =Maximum!T6 -> 1315.6 | K6: =Maximum!U6 -> 1335.014 | V6: =A6 -> 3.69 | W6: =Operational!V6 -> 1.41 | X6: =Operational!W6 -> 0.96 | Y6: =Operational!X6 -> 2.48 | Z6: =Operational!Y6 -> 2.14 | AA6: =Operational!AD6 -> 127 | AB6: =Operational!AE6 -> 140 | AC6: =Operational!AF6 -> 127 | AD6: =Operational!AG6 -> 140 | AE6: =Maximum!Q6 -> 67.13 | AF6: =Maximum!AD6 -> 399 | AG6: =Maximum!V6 -> 3.65 | AH6: =Maximum!W6 -> 3.26 | AI6: =Maximum!X6 -> 4.5 | AJ6: =Maximum!Y6 -> 3.37 | AK6: =W5-W6 -> -0.05 | AL6: =X5-X6 -> -0.02 | AM6: =Y5-Y6 -> -0.02 | AN6: =Z5-Z6 -> -0.05 | AO6: =AG5-AG6 -> -0.18 | AP6: =AH5-AH6 -> -0.2 | AQ6: =AI5-AI6 -> -0.12 | AR6: =AJ5-AJ6 -> -0.14
A7: =Operational!Q7 -> 4.67 | B7: =Operational!R7 -> 1268.233 | C7: =Operational!S7 -> 1288.044 | D7: =Operational!T7 -> 1308.758 | E7: =Operational!U7 -> 1328.045 | G7: =Maximum!Q7 -> 66.21 | H7: =Maximum!R7 -> 1274.952 | I7: =Maximum!S7 -> 1294.931 | J7: =Maximum!T7 -> 1315.509 | K7: =Maximum!U7 -> 1334.92 | V7: =A7 -> 4.67 | W7: =Operational!V7 -> 1.35 | X7: =Operational!W7 -> 1.02 | Y7: =Operational!X7 -> 2.48 | Z7: =Operational!Y7 -> 2.09 | AA7: =Operational!AD7 -> 127 | AB7: =Operational!AE7 -> 140 | AC7: =Operational!AF7 -> 127 | AD7: =Operational!AG7 -> 140 | AE7: =Maximum!Q7 -> 66.21 | AF7: =Maximum!AD7 -> 399 | AG7: =Maximum!V7 -> 3.77 | AH7: =Maximum!W7 -> 3.46 | AI7: =Maximum!X7 -> 4.65 | AJ7: =Maximum!Y7 -> 3.45 | AK7: =W6-W7 -> 0.06 | AL7: =X6-X7 -> -0.06 | AM7: =Y6-Y7 -> 0 | AN7: =Z6-Z7 -> 0.05 | AO7: =AG6-AG7 -> -0.12 | AP7: =AH6-AH7 -> -0.2 | AQ7: =AI6-AI7 -> -0.15 | AR7: =AJ6-AJ7 -> -0.08
A8: =Operational!Q8 -> 5.61 | B8: =Operational!R8 -> 1268.316 | C8: =Operational!S8 -> 1288.13 | D8: =Operational!T8 -> 1308.842 | E8: =Operational!U8 -> 1328.132 | G8: =Maximum!Q8 -> 65.36 | H8: =Maximum!R8 -> 1274.863 | I8: =Maximum!S8 -> 1294.84 | J8: =Maximum!T8 -> 1315.421 | K8: =Maximum!U8 -> 1334.829 | V8: =A8 -> 5.61 | W8: =Operational!V8 -> 1.38 | X8: =Operational!W8 -> 1.03 | Y8: =Operational!X8 -> 2.45 | Z8: =Operational!Y8 -> 2.09 | AA8: =Operational!AD8 -> 128 | AB8: =Operational!AE8 -> 140 | AC8: =Operational!AF8 -> 128 | AD8: =Operational!AG8 -> 140 | AE8: =Maximum!Q8 -> 65.36 | AF8: =Maximum!AD8 -> 399 | AG8: =Maximum!V8 -> 3.85 | AH8: =Maximum!W8 -> 3.6 | AI8: =Maximum!X8 -> 4.76 | AJ8: =Maximum!Y8 -> 3.53 | AK8: =W7-W8 -> -0.03 | AL8: =X7-X8 -> -0.01 | AM8: =Y7-Y8 -> 0.03 | AN8: =Z7-Z8 -> 0 | AO8: =AG7-AG8 -> -0.08 | AP8: =AH7-AH8 -> -0.14 | AQ8: =AI7-AI8 -> -0.11 | AR8: =AJ7-AJ8 -> -0.08
A9: =Operational!Q9 -> 6.5 | B9: =Operational!R9 -> 1268.398 | C9: =Operational!S9 -> 1288.214 | D9: =Operational!T9 -> 1308.925 | E9: =Operational!U9 -> 1328.218 | G9: =Maximum!Q9 -> 64.48 | H9: =Maximum!R9 -> 1274.777 | I9: =Maximum!S9 -> 1294.752 | J9: =Maximum!T9 -> 1315.335 | K9: =Maximum!U9 -> 1334.744 | V9: =A9 -> 6.5 | W9: =Operational!V9 -> 1.36 | X9: =Operational!W9 -> 1.01 | Y9: =Operational!X9 -> 2.46 | Z9: =Operational!Y9 -> 2.07 | AA9: =Operational!AD9 -> 129 | AB9: =Operational!AE9 -> 140 | AC9: =Operational!AF9 -> 129 | AD9: =Operational!AG9 -> 140 | AE9: =Maximum!Q9 -> 64.48 | AF9: =Maximum!AD9 -> 399 | AG9: =Maximum!V9 -> 3.98 | AH9: =Maximum!W9 -> 3.76 | AI9: =Maximum!X9 -> 4.86 | AJ9: =Maximum!Y9 -> 3.56 | AK9: =W8-W9 -> 0.02 | AL9: =X8-X9 -> 0.02 | AM9: =Y8-Y9 -> -0.01 | AN9: =Z8-Z9 -> 0.02 | AO9: =AG8-AG9 -> -0.13 | AP9: =AH8-AH9 -> -0.16 | AQ9: =AI8-AI9 -> -0.1 | AR9: =AJ8-AJ9 -> -0.03
A10: =Operational!Q10 -> 7.41 | B10: =Operational!R10 -> 1268.48 | C10: =Operational!S10 -> 1288.298 | D10: =Operational!T10 -> 1309.008 | E10: =Operational!U10 -> 1328.303 | G10: =Maximum!Q10 -> 63.61 | H10: =Maximum!R10 -> 1274.689 | I10: =Maximum!S10 -> 1294.664 | J10: =Maximum!T10 -> 1315.248 | K10: =Maximum!U10 -> 1334.655 | V10: =A10 -> 7.41 | W10: =Operational!V10 -> 1.36 | X10: =Operational!W10 -> 1.04 | Y10: =Operational!X10 -> 2.49 | Z10: =Operational!Y10 -> 2.08 | AA10: =Operational!AD10 -> 129 | AB10: =Operational!AE10 -> 140 | AC10: =Operational!AF10 -> 129 | AD10: =Operational!AG10 -> 140 | AE10: =Maximum!Q10 -> 63.61 | AF10: =Maximum!AD10 -> 399 | AG10: =Maximum!V10 -> 4.14 | AH10: =Maximum!W10 -> 3.9 | AI10: =Maximum!X10 -> 4.96 | AJ10: =Maximum!Y10 -> 3.65 | AK10: =W9-W10 -> 0 | AL10: =X9-X10 -> -0.03 | AM10: =Y9-Y10 -> -0.03 | AN10: =Z9-Z10 -> -0.01 | AO10: =AG9-AG10 -> -0.16 | AP10: =AH9-AH10 -> -0.14 | AQ10: =AI9-AI10 -> -0.1 | AR10: =AJ9-AJ10 -> -0.09
A11: =Operational!Q11 -> 8.3 | B11: =Operational!R11 -> 1268.559 | C11: =Operational!S11 -> 1288.379 | D11: =Operational!T11 -> 1309.088 | E11: =Operational!U11 -> 1328.388 | G11: =Maximum!Q11 -> 62.67 | H11: =Maximum!R11 -> 1274.604 | I11: =Maximum!S11 -> 1294.576 | J11: =Maximum!T11 -> 1315.162 | K11: =Maximum!U11 -> 1334.568 | V11: =A11 -> 8.3 | W11: =Operational!V11 -> 1.35 | X11: =Operational!W11 -> 1.04 | Y11: =Operational!X11 -> 2.48 | Z11: =Operational!Y11 -> 2.13 | AA11: =Operational!AD11 -> 130 | AB11: =Operational!AE11 -> 141 | AC11: =Operational!AF11 -> 130 | AD11: =Operational!AG11 -> 141 | AE11: =Maximum!Q11 -> 62.67 | AF11: =Maximum!AD11 -> 399 | AG11: =Maximum!V11 -> 4.36 | AH11: =Maximum!W11 -> 4.06 | AI11: =Maximum!X11 -> 5.08 | AJ11: =Maximum!Y11 -> 3.75 | AK11: =W10-W11 -> 0.01 | AL11: =X10-X11 -> 0 | AM11: =Y10-Y11 -> 0.01 | AN11: =Z10-Z11 -> -0.05 | AO11: =AG10-AG11 -> -0.22 | AP11: =AH10-AH11 -> -0.16 | AQ11: =AI10-AI11 -> -0.12 | AR11: =AJ10-AJ11 -> -0.1
A12: =Operational!Q12 -> 9.17 | B12: =Operational!R12 -> 1268.64 | C12: =Operational!S12 -> 1288.461 | D12: =Operational!T12 -> 1309.17 | E12: =Operational!U12 -> 1328.472 | G12: =Maximum!Q12 -> 61.85 | H12: =Maximum!R12 -> 1274.516 | I12: =Maximum!S12 -> 1294.488 | J12: =Maximum!T12 -> 1315.074 | K12: =Maximum!U12 -> 1334.481 | V12: =A12 -> 9.17 | W12: =Operational!V12 -> 1.33 | X12: =Operational!W12 -> 1.06 | Y12: =Operational!X12 -> 2.51 | Z12: =Operational!Y12 -> 2.13 | AA12: =Operational!AD12 -> 131 | AB12: =Operational!AE12 -> 141 | AC12: =Operational!AF12 -> 131 | AD12: =Operational!AG12 -> 141 | AE12: =Maximum!Q12 -> 61.85 | AF12: =Maximum!AD12 -> 399 | AG12: =Maximum!V12 -> 4.57 | AH12: =Maximum!W12 -> 4.25 | AI12: =Maximum!X12 -> 5.26 | AJ12: =Maximum!Y12 -> 3.87 | AK12: =W11-W12 -> 0.02 | AL12: =X11-X12 -> -0.02 | AM12: =Y11-Y12 -> -0.03 | AN12: =Z11-Z12 -> 0 | AO12: =AG11-AG12 -> -0.21 | AP12: =AH11-AH12 -> -0.19 | AQ12: =AI11-AI12 -> -0.18 | AR12: =AJ11-AJ12 -> -0.12
A13: =Operational!Q13 -> 10.05 | B13: =Operational!R13 -> 1268.718 | C13: =Operational!S13 -> 1288.54 | D13: =Operational!T13 -> 1309.249 | E13: =Operational!U13 -> 1328.553 | G13: =Maximum!Q13 -> 60.99 | H13: =Maximum!R13 -> 1274.427 | I13: =Maximum!S13 -> 1294.397 | J13: =Maximum!T13 -> 1314.986 | K13: =Maximum!U13 -> 1334.393 | V13: =A13 -> 10.05 | W13: =Operational!V13 -> 1.32 | X13: =Operational!W13 -> 1.08 | Y13: =Operational!X13 -> 2.51 | Z13: =Operational!Y13 -> 2.07 | AA13: =Operational!AD13 -> 132 | AB13: =Operational!AE13 -> 141 | AC13: =Operational!AF13 -> 132 | AD13: =Operational!AG13 -> 141 | AE13: =Maximum!Q13 -> 60.99 | AF13: =Maximum!AD13 -> 399 | AG13: =Maximum!V13 -> 4.62 | AH13: =Maximum!W13 -> 4.39 | AI13: =Maximum!X13 -> 5.33 | AJ13: =Maximum!Y13 -> 3.92 | AK13: =W12-W13 -> 0.01 | AL13: =X12-X13 -> -0.02 | AM13: =Y12-Y13 -> 0 | AN13: =Z12-Z13 -> 0.06 | AO13: =AG12-AG13 -> -0.05 | AP13: =AH12-AH13 -> -0.14 | AQ13: =AI12-AI13 -> -0.07 | AR13: =AJ12-AJ13 -> -0.05
A14: =Operational!Q14 -> 10.95 | B14: =Operational!R14 -> 1268.795 | C14: =Operational!S14 -> 1288.619 | D14: =Operational!T14 -> 1309.329 | E14: =Operational!U14 -> 1328.634 | G14: =Maximum!Q14 -> 60.11 | H14: =Maximum!R14 -> 1274.341 | I14: =Maximum!S14 -> 1294.31 | J14: =Maximum!T14 -> 1314.902 | K14: =Maximum!U14 -> 1334.308 | V14: =A14 -> 10.95 | W14: =Operational!V14 -> 1.31 | X14: =Operational!W14 -> 1.12 | Y14: =Operational!X14 -> 2.56 | Z14: =Operational!Y14 -> 2.03 | AA14: =Operational!AD14 -> 133 | AB14: =Operational!AE14 -> 141 | AC14: =Operational!AF14 -> 133 | AD14: =Operational!AG14 -> 141 | AE14: =Maximum!Q14 -> 60.11 | AF14: =Maximum!AD14 -> 399 | AG14: =Maximum!V14 -> 4.75 | AH14: =Maximum!W14 -> 4.52 | AI14: =Maximum!X14 -> 5.43 | AJ14: =Maximum!Y14 -> 3.93 | AK14: =W13-W14 -> 0.01 | AL14: =X13-X14 -> -0.04 | AM14: =Y13-Y14 -> -0.05 | AN14: =Z13-Z14 -> 0.04 | AO14: =AG13-AG14 -> -0.13 | AP14: =AH13-AH14 -> -0.13 | AQ14: =AI13-AI14 -> -0.1 | AR14: =AJ13-AJ14 -> -0.01
... A84: =Operational!Q84 -> 70.11 | B84: =Operational!R84 -> 1274.391 | C84: =Operational!S84 -> 1294.266 | D84: =Operational!T84 -> 1314.936 | E84: =Operational!U84 -> 1334.331 | G84: =Maximum!Q84 -> 1.45 | H84: =Maximum!R84 -> 1268.829 | I84: =Maximum!S84 -> 1288.717 | J84: =Maximum!T84 -> 1309.398 | K84: =Maximum!U84 -> 1328.722 | V84: =A84 -> 70.11 | W84: =Operational!V84 -> 1.06 | X84: =Operational!W84 -> 0.82 | Y84: =Operational!X84 -> 2.29 | Z84: =Operational!Y84 -> 1.67 | AA84: =Operational!AD84 -> 214 | AB84: =Operational!AE84 -> 213 | AC84: =Operational!AF84 -> 214 | AD84: =Operational!AG84 -> 213 | AE84: =Maximum!Q84 -> 1.45 | AF84: =Maximum!AD84 -> 399 | AG84: =Maximum!V84 -> 9.13 | AH84: =Maximum!W84 -> 8.76 | AI84: =Maximum!X84 -> 9.7 | AJ84: =Maximum!Y84 -> 7.01 | AK84: =W83-W84 -> -0.02 | AL84: =X83-X84 -> -0.03 | AM84: =Y83-Y84 -> 0.02 | AN84: =Z83-Z84 -> 0.1 | AO84: =AG83-AG84 -> 0 | AP84: =AH83-AH84 -> 0.04 | AQ84: =AI83-AI84 -> -0.06 | AR84: =AJ83-AJ84 -> -0.05
G85: =Maximum!Q85 -> 0.65 | H85: =Maximum!R85 -> 1268.754 | I85: =Maximum!S85 -> 1288.641 | J85: =Maximum!T85 -> 1309.323 | K85: =Maximum!U85 -> 1328.645 | AE85: =Maximum!Q85 -> 0.65 | AF85: =Maximum!AD85 -> 399 | AG85: =Maximum!V85 -> 9.17 | AH85: =Maximum!W85 -> 8.8 | AI85: =Maximum!X85 -> 9.68 | AJ85: =Maximum!Y85 -> 6.98 | AK85: =W84-W85 -> 1.06 | AL85: =X84-X85 -> 0.82 | AM85: =Y84-Y85 -> 2.29 | AN85: =Z84-Z85 -> 1.67 | AO85: =AG84-AG85 -> -0.04 | AP85: =AH84-AH85 -> -0.04 | AQ85: =AI84-AI85 -> 0.02 | AR85: =AJ84-AJ85 -> 0.03
G86: =Maximum!Q86 -> -0.16 | H86: =Maximum!R86 -> 1268.678 | I86: =Maximum!S86 -> 1288.564 | J86: =Maximum!T86 -> 1309.245 | K86: =Maximum!U86 -> 1328.566 | AE86: =Maximum!Q86 -> -0.16 | AF86: =Maximum!AD86 -> 399 | AG86: =Maximum!V86 -> 9.2 | AH86: =Maximum!W86 -> 8.83 | AI86: =Maximum!X86 -> 9.72 | AJ86: =Maximum!Y86 -> 7.02 | AK86: =W85-W86 -> 0 | AL86: =X85-X86 -> 0 | AM86: =Y85-Y86 -> 0 | AN86: =Z85-Z86 -> 0 | AO86: =AG85-AG86 -> -0.03 | AP86: =AH85-AH86 -> -0.03 | AQ86: =AI85-AI86 -> -0.04 | AR86: =AJ85-AJ86 -> -0.04
AE87: =Maximum!Q87 -> 0 | AF87: =Maximum!AD87 -> 399 | AG87: =Maximum!V87 -> 0 | AH87: =Maximum!W87 -> 0 | AI87: =Maximum!X87 -> 0 | AJ87: =Maximum!Y87 -> 0 | AK87: =W86-W87 -> 0 | AL87: =X86-X87 -> 0 | AM87: =Y86-Y87 -> 0 | AN87: =Z86-Z87 -> 0 | AO87: =AG86-AG87 -> 9.2 | AP87: =AH86-AH87 -> 8.83 | AQ87: =AI86-AI87 -> 9.72 | AR87: =AJ86-AJ87 -> 7.02

Sheet Operational
A1: Case Temp(℃) | B1: dWL/dT | C1: dWL/dT | D1: dWL/dT | E1: dWL/dT | F1: Max | G1: Min | Q1: Case Temp(℃) | R1: Wavelength(nm)_CH1 | S1: Wavelength(nm)_CH2 | T1: Wavelength(nm)_CH3 | U1: Wavelength(nm)_CH4 | V1: Power_CH1 | W1: Power_CH2 | X1: Power_CH3 | Y1: Power_CH4 | Z1: dWL1/dT | AA1: dWL2/dT | AB1: dWL3/dT | AC1: dWL4/dT | AD1: CH1_DDMI_Bias_N | AE1: CH2_DDMI_Bias_N | AF1: CH3_DDMI_Bias_N | AG1: CH4_DDMI_Bias_N
A2: =Q2 -> -0.21 | B2: =Z2 -> 0.08 | C2: =AA2 -> 0.08 | D2: =AB2 -> 0.08 | E2: =AC2 -> 0.08 | F2: 0.2 | G2: 0 | Q2: ='1_Operational'!Q2 -> -0.21 | R2: ='1_Operational'!R2 -> 1267.809 | S2: ='2_Operational'!R2 -> 1287.61 | T2: ='3_Operational'!R2 -> 1308.322 | U2: ='4_Operational'!R2 -> 1327.604 | V2: ='1_Operational'!T2 -> 1.4 | W2: ='2_Operational'!T2 -> 0.9 | X2: ='3_Operational'!T2 -> 2.49 | Y2: ='4_Operational'!T2 -> 2.17 | Z2: ='1_Operational'!S2 -> 0.08 | AA2: ='2_Operational'!S2 -> 0.08 | AB2: ='3_Operational'!S2 -> 0.08 | AC2: ='4_Operational'!S2 -> 0.08 | AD2: ='1_Operational'!AD2 -> 124 | AE2: ='1_Operational'!AE2 -> 140 | AF2: ='3_Operational'!Z2 -> 124 | AG2: ='4_Operational'!AA2 -> 140
A3: =Q3 -> 0.75 | B3: =Z3 -> 0.09 | C3: =AA3 -> 0.09 | D3: =AB3 -> 0.09 | E3: =AC3 -> 0.09 | F3: 0.2 | G3: 0 | Q3: ='1_Operational'!Q3 -> 0.75 | R3: ='1_Operational'!R3 -> 1267.892 | S3: ='2_Operational'!R3 -> 1287.694 | T3: ='3_Operational'!R3 -> 1308.407 | U3: ='4_Operational'!R3 -> 1327.69 | V3: ='1_Operational'!T3 -> 1.29 | W3: ='2_Operational'!T3 -> 0.86 | X3: ='3_Operational'!T3 -> 2.49 | Y3: ='4_Operational'!T3 -> 2.11 | Z3: ='1_Operational'!S3 -> 0.09 | AA3: ='2_Operational'!S3 -> 0.09 | AB3: ='3_Operational'!S3 -> 0.09 | AC3: ='4_Operational'!S3 -> 0.09 | AD3: ='1_Operational'!AD3 -> 124 | AE3: ='1_Operational'!AE3 -> 140 | AF3: ='3_Operational'!Z3 -> 124 | AG3: ='4_Operational'!AA3 -> 140
A4: =Q4 -> 1.76 | B4: =Z4 -> 0.08 | C4: =AA4 -> 0.09 | D4: =AB4 -> 0.09 | E4: =AC4 -> 0.09 | F4: 0.2 | G4: 0 | Q4: ='1_Operational'!Q4 -> 1.76 | R4: ='1_Operational'!R4 -> 1267.976 | S4: ='2_Operational'!R4 -> 1287.78 | T4: ='3_Operational'!R4 -> 1308.495 | U4: ='4_Operational'!R4 -> 1327.778 | V4: ='1_Operational'!T4 -> 1.31 | W4: ='2_Operational'!T4 -> 0.89 | X4: ='3_Operational'!T4 -> 2.41 | Y4: ='4_Operational'!T4 -> 2.08 | Z4: ='1_Operational'!S4 -> 0.08 | AA4: ='2_Operational'!S4 -> 0.09 | AB4: ='3_Operational'!S4 -> 0.09 | AC4: ='4_Operational'!S4 -> 0.09 | AD4: ='1_Operational'!AD4 -> 125 | AE4: ='1_Operational'!AE4 -> 140 | AF4: ='3_Operational'!Z4 -> 125 | AG4: ='4_Operational'!AA4 -> 140
A5: =Q5 -> 2.7 | B5: =Z5 -> 0.09 | C5: =AA5 -> 0.09 | D5: =AB5 -> 0.09 | E5: =AC5 -> 0.09 | F5: 0.2 | G5: 0 | Q5: ='1_Operational'!Q5 -> 2.7 | R5: ='1_Operational'!R5 -> 1268.061 | S5: ='2_Operational'!R5 -> 1287.868 | T5: ='3_Operational'!R5 -> 1308.583 | U5: ='4_Operational'!R5 -> 1327.866 | V5: ='1_Operational'!T5 -> 1.36 | W5: ='2_Operational'!T5 -> 0.94 | X5: ='3_Operational'!T5 -> 2.46 | Y5: ='4_Operational'!T5 -> 2.09 | Z5: ='1_Operational'!S5 -> 0.09 | AA5: ='2_Operational'!S5 -> 0.09 | AB5: ='3_Operational'!S5 -> 0.09 | AC5: ='4_Operational'!S5 -> 0.09 | AD5: ='1_Operational'!AD5 -> 126 | AE5: ='1_Operational'!AE5 -> 140 | AF5: ='3_Operational'!Z5 -> 126 | AG5: ='4_Operational'!AA5 -> 140
A6: =Q6 -> 3.69 | B6: =Z6 -> 0.09 | C6: =AA6 -> 0.09 | D6: =AB6 -> 0.09 | E6: =AC6 -> 0.09 | F6: 0.2 | G6: 0 | Q6: ='1_Operational'!Q6 -> 3.69 | R6: ='1_Operational'!R6 -> 1268.148 | S6: ='2_Operational'!R6 -> 1287.957 | T6: ='3_Operational'!R6 -> 1308.671 | U6: ='4_Operational'!R6 -> 1327.956 | V6: ='1_Operational'!T6 -> 1.41 | W6: ='2_Operational'!T6 -> 0.96 | X6: ='3_Operational'!T6 -> 2.48 | Y6: ='4_Operational'!T6 -> 2.14 | Z6: ='1_Operational'!S6 -> 0.09 | AA6: ='2_Operational'!S6 -> 0.09 | AB6: ='3_Operational'!S6 -> 0.09 | AC6: ='4_Operational'!S6 -> 0.09 | AD6: ='1_Operational'!AD6 -> 127 | AE6: ='1_Operational'!AE6 -> 140 | AF6: ='3_Operational'!Z6 -> 127 | AG6: ='4_Operational'!AA6 -> 140
A7: =Q7 -> 4.67 | B7: =Z7 -> 0.09 | C7: =AA7 -> 0.09 | D7: =AB7 -> 0.09 | E7: =AC7 -> 0.09 | F7: 0.2 | G7: 0 | Q7: ='1_Operational'!Q7 -> 4.67 | R7: ='1_Operational'!R7 -> 1268.233 | S7: ='2_Operational'!R7 -> 1288.044 | T7: ='3_Operational'!R7 -> 1308.758 | U7: ='4_Operational'!R7 -> 1328.045 | V7: ='1_Operational'!T7 -> 1.35 | W7: ='2_Operational'!T7 -> 1.02 | X7: ='3_Operational'!T7 -> 2.48 | Y7: ='4_Operational'!T7 -> 2.09 | Z7: ='1_Operational'!S7 -> 0.09 | AA7: ='2_Operational'!S7 -> 0.09 | AB7: ='3_Operational'!S7 -> 0.09 | AC7: ='4_Operational'!S7 -> 0.09 | AD7: ='1_Operational'!AD7 -> 127 | AE7: ='1_Operational'!AE7 -> 140 | AF7: ='3_Operational'!Z7 -> 127 | AG7: ='4_Operational'!AA7 -> 140
A8: =Q8 -> 5.61 | B8: =Z8 -> 0.09 | C8: =AA8 -> 0.09 | D8: =AB8 -> 0.09 | E8: =AC8 -> 0.09 | F8: 0.2 | G8: 0 | Q8: ='1_Operational'!Q8 -> 5.61 | R8: ='1_Operational'!R8 -> 1268.316 | S8: ='2_Operational'!R8 -> 1288.13 | T8: ='3_Operational'!R8 -> 1308.842 | U8: ='4_Operational'!R8 -> 1328.132 | V8: ='1_Operational'!T8 -> 1.38 | W8: ='2_Operational'!T8 -> 1.03 | X8: ='3_Operational'!T8 -> 2.45 | Y8: ='4_Operational'!T8 -> 2.09 | Z8: ='1_Operational'!S8 -> 0.09 | AA8: ='2_Operational'!S8 -> 0.09 | AB8: ='3_Operational'!S8 -> 0.09 | AC8: ='4_Operational'!S8 -> 0.09 | AD8: ='1_Operational'!AD8 -> 128 | AE8: ='1_Operational'!AE8 -> 140 | AF8: ='3_Operational'!Z8 -> 128 | AG8: ='4_Operational'!AA8 -> 140
A9: =Q9 -> 6.5 | B9: =Z9 -> 0.09 | C9: =AA9 -> 0.09 | D9: =AB9 -> 0.09 | E9: =AC9 -> 0.1 | F9: 0.2 | G9: 0 | Q9: ='1_Operational'!Q9 -> 6.5 | R9: ='1_Operational'!R9 -> 1268.398 | S9: ='2_Operational'!R9 -> 1288.214 | T9: ='3_Operational'!R9 -> 1308.925 | U9: ='4_Operational'!R9 -> 1328.218 | V9: ='1_Operational'!T9 -> 1.36 | W9: ='2_Operational'!T9 -> 1.01 | X9: ='3_Operational'!T9 -> 2.46 | Y9: ='4_Operational'!T9 -> 2.07 | Z9: ='1_Operational'!S9 -> 0.09 | AA9: ='2_Operational'!S9 -> 0.09 | AB9: ='3_Operational'!S9 -> 0.09 | AC9: ='4_Operational'!S9 -> 0.1 | AD9: ='1_Operational'!AD9 -> 129 | AE9: ='1_Operational'!AE9 -> 140 | AF9: ='3_Operational'!Z9 -> 129 | AG9: ='4_Operational'!AA9 -> 140
A10: =Q10 -> 7.41 | B10: =Z10 -> 0.09 | C10: =AA10 -> 0.09 | D10: =AB10 -> 0.09 | E10: =AC10 -> 0.09 | F10: 0.2 | G10: 0 | Q10: ='1_Operational'!Q10 -> 7.41 | R10: ='1_Operational'!R10 -> 1268.48 | S10: ='2_Operational'!R10 -> 1288.298 | T10: ='3_Operational'!R10 -> 1309.008 | U10: ='4_Operational'!R10 -> 1328.303 | V10: ='1_Operational'!T10 -> 1.36 | W10: ='2_Operational'!T10 -> 1.04 | X10: ='3_Operational'!T10 -> 2.49 | Y10: ='4_Operational'!T10 -> 2.08 | Z10: ='1_Operational'!S10 -> 0.09 | AA10: ='2_Operational'!S10 -> 0.09 | AB10: ='3_Operational'!S10 -> 0.09 | AC10: ='4_Operational'!S10 -> 0.09 | AD10: ='1_Operational'!AD10 -> 129 | AE10: ='1_Operational'!AE10 -> 140 | AF10: ='3_Operational'!Z10 -> 129 | AG10: ='4_Operational'!AA10 -> 140
A11: =Q11 -> 8.3 | B11: =Z11 -> 0.09 | C11: =AA11 -> 0.09 | D11: =AB11 -> 0.09 | E11: =AC11 -> 0.1 | F11: 0.2 | G11: 0 | Q11: ='1_Operational'!Q11 -> 8.3 | R11: ='1_Operational'!R11 -> 1268.559 | S11: ='2_Operational'!R11 -> 1288.379 | T11: ='3_Operational'!R11 -> 1309.088 | U11: ='4_Operational'!R11 -> 1328.388 | V11: ='1_Operational'!T11 -> 1.35 | W11: ='2_Operational'!T11 -> 1.04 | X11: ='3_Operational'!T11 -> 2.48 | Y11: ='4_Operational'!T11 -> 2.13 | Z11: ='1_Operational'!S11 -> 0.09 | AA11: ='2_Operational'!S11 -> 0.09 | AB11: ='3_Operational'!S11 -> 0.09 | AC11: ='4_Operational'!S11 -> 0.1 | AD11: ='1_Operational'!AD11 -> 130 | AE11: ='1_Operational'!AE11 -> 141 | AF11: ='3_Operational'!Z11 -> 130 | AG11: ='4_Operational'!AA11 -> 141
A12: =Q12 -> 9.17 | B12: =Z12 -> 0.09 | C12: =AA12 -> 0.09 | D12: =AB12 -> 0.09 | E12: =AC12 -> 0.1 | F12: 0.2 | G12: 0 | Q12: ='1_Operational'!Q12 -> 9.17 | R12: ='1_Operational'!R12 -> 1268.64 | S12: ='2_Operational'!R12 -> 1288.461 | T12: ='3_Operational'!R12 -> 1309.17 | U12: ='4_Operational'!R12 -> 1328.472 | V12: ='1_Operational'!T12 -> 1.33 | W12: ='2_Operational'!T12 -> 1.06 | X12: ='3_Operational'!T12 -> 2.51 | Y12: ='4_Operational'!T12 -> 2.13 | Z12: ='1_Operational'!S12 -> 0.09 | AA12: ='2_Operational'!S12 -> 0.09 | AB12: ='3_Operational'!S12 -> 0.09 | AC12: ='4_Operational'!S12 -> 0.1 | AD12: ='1_Operational'!AD12 -> 131 | AE12: ='1_Operational'!AE12 -> 141 | AF12: ='3_Operational'!Z12 -> 131 | AG12: ='4_Operational'!AA12 -> 141
A13: =Q13 -> 10.05 | B13: =Z13 -> 0.09 | C13: =AA13 -> 0.09 | D13: =AB13 -> 0.09 | E13: =AC13 -> 0.09 | F13: 0.2 | G13: 0 | Q13: ='1_Operational'!Q13 -> 10.05 | R13: ='1_Operational'!R13 -> 1268.718 | S13: ='2_Operational'!R13 -> 1288.54 | T13: ='3_Operational'!R13 -> 1309.249 | U13: ='4_Operational'!R13 -> 1328.553 | V13: ='1_Operational'!T13 -> 1.32 | W13: ='2_Operational'!T13 -> 1.08 | X13: ='3_Operational'!T13 -> 2.51 | Y13: ='4_Operational'!T13 -> 2.07 | Z13: ='1_Operational'!S13 -> 0.09 | AA13: ='2_Operational'!S13 -> 0.09 | AB13: ='3_Operational'!S13 -> 0.09 | AC13: ='4_Operational'!S13 -> 0.09 | AD13: ='1_Operational'!AD13 -> 132 | AE13: ='1_Operational'!AE13 -> 141 | AF13: ='3_Operational'!Z13 -> 132 | AG13: ='4_Operational'!AA13 -> 141
... A84: =Q84 -> 70.11 | B84: =Z84 -> 0.11 | C84: =AA84 -> 0.11 | D84: =AB84 -> 0.11 | E84: =AC84 -> 0.11 | F84: 0.2 | G84: 0 | Q84: ='1_Operational'!Q84 -> 70.11 | R84: ='1_Operational'!R84 -> 1274.391 | S84: ='2_Operational'!R84 -> 1294.266 | T84: ='3_Operational'!R84 -> 1314.936 | U84: ='4_Operational'!R84 -> 1334.331 | V84: ='1_Operational'!T84 -> 1.06 | W84: ='2_Operational'!T84 -> 0.82 | X84: ='3_Operational'!T84 -> 2.29 | Y84: ='4_Operational'!T84 -> 1.67 | Z84: ='1_Operational'!S84 -> 0.11 | AA84: ='2_Operational'!S84 -> 0.11 | AB84: ='3_Operational'!S84 -> 0.11 | AC84: ='4_Operational'!S84 -> 0.11 | AD84: ='1_Operational'!AD84 -> 214 | AE84: ='1_Operational'!AE84 -> 213 | AF84: ='3_Operational'!Z84 -> 214 | AG84: ='4_Operational'!AA84 -> 213

Sheet Maximum
A1: Case Temp(℃) | B1: dWL/dT | C1: dWL/dT | D1: dWL/dT | E1: dWL/dT | F1: Max | G1: Min | Q1: Case Temp(℃) | R1: Wavelength(nm)_CH1 | S1: Wavelength(nm)_CH2 | T1: Wavelength(nm)_CH3 | U1: Wavelength(nm)_CH4 | V1: Power_CH1_M | W1: Power_CH2_M | X1: Power_CH3_M | Y1: Power_CH4_M | Z1: dWL1/dT | AA1: dWL2/dT | AB1: dWL3/dT | AC1: dWL4/dT | AD1: CH1_DDMI_Bias_M | AE1: CH2_DDMI_Bias_M | AF1: CH3_DDMI_Bias_M | AG1: CH4_DDMI_Bias_M
F2: 0.2 | G2: 0 | Q2: ='1_Maximum'!Q2 -> 70.77 | R2: ='1_Maximum'!R2 -> 1275.393 | S2: ='2_Maximum'!R2 -> 1295.377 | T2: ='3_Maximum'!R2 -> 1315.948 | U2: ='4_Maximum'!R2 -> 1335.366 | V2: ='1_Maximum'!T2 -> 2.83 | W2: ='2_Maximum'!T2 -> 2.57 | X2: ='3_Maximum'!T2 -> 3.98 | Y2: ='4_Maximum'!T2 -> 2.9 | Z2: ='1_Maximum'!S2 -> 0.1 | AA2: ='2_Maximum'!S2 -> 0.1 | AB2: ='3_Maximum'!S2 -> 0.1 | AC2: ='4_Maximum'!S2 -> 0.1 | AD2: 399 | AE2: 399 | AF2: 399 | AG2: 399
A3: =Q3 -> 69.81 | B3: =Z3 -> 0.09 | C3: =AA3 -> 0.09 | D3: =AB3 -> 0.09 | E3: =AC3 -> 0.09 | F3: 0.2 | G3: 0 | Q3: ='1_Maximum'!Q3 -> 69.81 | R3: ='1_Maximum'!R3 -> 1275.306 | S3: ='2_Maximum'!R3 -> 1295.29 | T3: ='3_Maximum'!R3 -> 1315.863 | U3: ='4_Maximum'!R3 -> 1335.279 | V3: ='1_Maximum'!T3 -> 3.08 | W3: ='2_Maximum'!T3 -> 2.74 | X3: ='3_Maximum'!T3 -> 4.14 | Y3: ='4_Maximum'!T3 -> 3 | Z3: ='1_Maximum'!S3 -> 0.09 | AA3: ='2_Maximum'!S3 -> 0.09 | AB3: ='3_Maximum'!S3 -> 0.09 | AC3: ='4_Maximum'!S3 -> 0.09 | AD3: 399 | AE3: 399 | AF3: 399 | AG3: 399
A4: =Q4 -> 69 | B4: =Z4 -> 0.11 | C4: =AA4 -> 0.11 | D4: =AB4 -> 0.11 | E4: =AC4 -> 0.11 | F4: 0.2 | G4: 0 | Q4: ='1_Maximum'!Q4 -> 69 | R4: ='1_Maximum'!R4 -> 1275.219 | S4: ='2_Maximum'!R4 -> 1295.202 | T4: ='3_Maximum'!R4 -> 1315.775 | U4: ='4_Maximum'!R4 -> 1335.193 | V4: ='1_Maximum'!T4 -> 3.26 | W4: ='2_Maximum'!T4 -> 2.86 | X4: ='3_Maximum'!T4 -> 4.28 | Y4: ='4_Maximum'!T4 -> 3.1 | Z4: ='1_Maximum'!S4 -> 0.11 | AA4: ='2_Maximum'!S4 -> 0.11 | AB4: ='3_Maximum'!S4 -> 0.11 | AC4: ='4_Maximum'!S4 -> 0.11 | AD4: 399 | AE4: 399 | AF4: 399 | AG4: 399
A5: =Q5 -> 68.02 | B5: =Z5 -> 0.09 | C5: =AA5 -> 0.09 | D5: =AB5 -> 0.09 | E5: =AC5 -> 0.09 | F5: 0.2 | G5: 0 | Q5: ='1_Maximum'!Q5 -> 68.02 | R5: ='1_Maximum'!R5 -> 1275.131 | S5: ='2_Maximum'!R5 -> 1295.112 | T5: ='3_Maximum'!R5 -> 1315.687 | U5: ='4_Maximum'!R5 -> 1335.104 | V5: ='1_Maximum'!T5 -> 3.47 | W5: ='2_Maximum'!T5 -> 3.06 | X5: ='3_Maximum'!T5 -> 4.38 | Y5: ='4_Maximum'!T5 -> 3.23 | Z5: ='1_Maximum'!S5 -> 0.09 | AA5: ='2_Maximum'!S5 -> 0.09 | AB5: ='3_Maximum'!S5 -> 0.09 | AC5: ='4_Maximum'!S5 -> 0.09 | AD5: 399 | AE5: 399 | AF5: 399 | AG5: 399
A6: =Q6 -> 67.13 | B6: =Z6 -> 0.1 | C6: =AA6 -> 0.1 | D6: =AB6 -> 0.1 | E6: =AC6 -> 0.1 | F6: 0.2 | G6: 0 | Q6: ='1_Maximum'!Q6 -> 67.13 | R6: ='1_Maximum'!R6 -> 1275.042 | S6: ='2_Maximum'!R6 -> 1295.022 | T6: ='3_Maximum'!R6 -> 1315.6 | U6: ='4_Maximum'!R6 -> 1335.014 | V6: ='1_Maximum'!T6 -> 3.65 | W6: ='2_Maximum'!T6 -> 3.26 | X6: ='3_Maximum'!T6 -> 4.5 | Y6: ='4_Maximum'!T6 -> 3.37 | Z6: ='1_Maximum'!S6 -> 0.1 | AA6: ='2_Maximum'!S6 -> 0.1 | AB6: ='3_Maximum'!S6 -> 0.1 | AC6: ='4_Maximum'!S6 -> 0.1 | AD6: 399 | AE6: 399 | AF6: 399 | AG6: 399
A7: =Q7 -> 66.21 | B7: =Z7 -> 0.1 | C7: =AA7 -> 0.1 | D7: =AB7 -> 0.1 | E7: =AC7 -> 0.1 | F7: 0.2 | G7: 0 | Q7: ='1_Maximum'!Q7 -> 66.21 | R7: ='1_Maximum'!R7 -> 1274.952 | S7: ='2_Maximum'!R7 -> 1294.931 | T7: ='3_Maximum'!R7 -> 1315.509 | U7: ='4_Maximum'!R7 -> 1334.92 | V7: ='1_Maximum'!T7 -> 3.77 | W7: ='2_Maximum'!T7 -> 3.46 | X7: ='3_Maximum'!T7 -> 4.65 | Y7: ='4_Maximum'!T7 -> 3.45 | Z7: ='1_Maximum'!S7 -> 0.1 | AA7: ='2_Maximum'!S7 -> 0.1 | AB7: ='3_Maximum'!S7 -> 0.1 | AC7: ='4_Maximum'!S7 -> 0.1 | AD7: 399 | AE7: 399 | AF7: 399 | AG7: 399
A8: =Q8 -> 65.36 | B8: =Z8 -> 0.1 | C8: =AA8 -> 0.11 | D8: =AB8 -> 0.1 | E8: =AC8 -> 0.11 | F8: 0.2 | G8: 0 | Q8: ='1_Maximum'!Q8 -> 65.36 | R8: ='1_Maximum'!R8 -> 1274.863 | S8: ='2_Maximum'!R8 -> 1294.84 | T8: ='3_Maximum'!R8 -> 1315.421 | U8: ='4_Maximum'!R8 -> 1334.829 | V8: ='1_Maximum'!T8 -> 3.85 | W8: ='2_Maximum'!T8 -> 3.6 | X8: ='3_Maximum'!T8 -> 4.76 | Y8: ='4_Maximum'!T8 -> 3.53 | Z8: ='1_Maximum'!S8 -> 0.1 | AA8: ='2_Maximum'!S8 -> 0.11 | AB8: ='3_Maximum'!S8 -> 0.1 | AC8: ='4_Maximum'!S8 -> 0.11 | AD8: 399 | AE8: 399 | AF8: 399 | AG8: 399
A9: =Q9 -> 64.48 | B9: =Z9 -> 0.1 | C9: =AA9 -> 0.1 | D9: =AB9 -> 0.1 | E9: =AC9 -> 0.1 | F9: 0.2 | G9: 0 | Q9: ='1_Maximum'!Q9 -> 64.48 | R9: ='1_Maximum'!R9 -> 1274.777 | S9: ='2_Maximum'!R9 -> 1294.752 | T9: ='3_Maximum'!R9 -> 1315.335 | U9: ='4_Maximum'!R9 -> 1334.744 | V9: ='1_Maximum'!T9 -> 3.98 | W9: ='2_Maximum'!T9 -> 3.76 | X9: ='3_Maximum'!T9 -> 4.86 | Y9: ='4_Maximum'!T9 -> 3.56 | Z9: ='1_Maximum'!S9 -> 0.1 | AA9: ='2_Maximum'!S9 -> 0.1 | AB9: ='3_Maximum'!S9 -> 0.1 | AC9: ='4_Maximum'!S9 -> 0.1 | AD9: 399 | AE9: 399 | AF9: 399 | AG9: 399
A10: =Q10 -> 63.61 | B10: =Z10 -> 0.1 | C10: =AA10 -> 0.1 | D10: =AB10 -> 0.1 | E10: =AC10 -> 0.1 | F10: 0.2 | G10: 0 | Q10: ='1_Maximum'!Q10 -> 63.61 | R10: ='1_Maximum'!R10 -> 1274.689 | S10: ='2_Maximum'!R10 -> 1294.664 | T10: ='3_Maximum'!R10 -> 1315.248 | U10: ='4_Maximum'!R10 -> 1334.655 | V10: ='1_Maximum'!T10 -> 4.14 | W10: ='2_Maximum'!T10 -> 3.9 | X10: ='3_Maximum'!T10 -> 4.96 | Y10: ='4_Maximum'!T10 -> 3.65 | Z10: ='1_Maximum'!S10 -> 0.1 | AA10: ='2_Maximum'!S10 -> 0.1 | AB10: ='3_Maximum'!S10 -> 0.1 | AC10: ='4_Maximum'!S10 -> 0.1 | AD10: 399 | AE10: 399 | AF10: 399 | AG10: 399
A11: =Q11 -> 62.67 | B11: =Z11 -> 0.09 | C11: =AA11 -> 0.09 | D11: =AB11 -> 0.09 | E11: =AC11 -> 0.09 | F11: 0.2 | G11: 0 | Q11: ='1_Maximum'!Q11 -> 62.67 | R11: ='1_Maximum'!R11 -> 1274.604 | S11: ='2_Maximum'!R11 -> 1294.576 | T11: ='3_Maximum'!R11 -> 1315.162 | U11: ='4_Maximum'!R11 -> 1334.568 | V11: ='1_Maximum'!T11 -> 4.36 | W11: ='2_Maximum'!T11 -> 4.06 | X11: ='3_Maximum'!T11 -> 5.08 | Y11: ='4_Maximum'!T11 -> 3.75 | Z11: ='1_Maximum'!S11 -> 0.09 | AA11: ='2_Maximum'!S11 -> 0.09 | AB11: ='3_Maximum'!S11 -> 0.09 | AC11: ='4_Maximum'!S11 -> 0.09 | AD11: 399 | AE11: 399 | AF11: 399 | AG11: 399
A12: =Q12 -> 61.85 | B12: =Z12 -> 0.11 | C12: =AA12 -> 0.11 | D12: =AB12 -> 0.11 | E12: =AC12 -> 0.11 | F12: 0.2 | G12: 0 | Q12: ='1_Maximum'!Q12 -> 61.85 | R12: ='1_Maximum'!R12 -> 1274.516 | S12: ='2_Maximum'!R12 -> 1294.488 | T12: ='3_Maximum'!R12 -> 1315.074 | U12: ='4_Maximum'!R12 -> 1334.481 | V12: ='1_Maximum'!T12 -> 4.57 | W12: ='2_Maximum'!T12 -> 4.25 | X12: ='3_Maximum'!T12 -> 5.26 | Y12: ='4_Maximum'!T12 -> 3.87 | Z12: ='1_Maximum'!S12 -> 0.11 | AA12: ='2_Maximum'!S12 -> 0.11 | AB12: ='3_Maximum'!S12 -> 0.11 | AC12: ='4_Maximum'!S12 -> 0.11 | AD12: 399 | AE12: 399 | AF12: 399 | AG12: 399
A13: =Q13 -> 60.99 | B13: =Z13 -> 0.1 | C13: =AA13 -> 0.11 | D13: =AB13 -> 0.1 | E13: =AC13 -> 0.1 | F13: 0.2 | G13: 0 | Q13: ='1_Maximum'!Q13 -> 60.99 | R13: ='1_Maximum'!R13 -> 1274.427 | S13: ='2_Maximum'!R13 -> 1294.397 | T13: ='3_Maximum'!R13 -> 1314.986 | U13: ='4_Maximum'!R13 -> 1334.393 | V13: ='1_Maximum'!T13 -> 4.62 | W13: ='2_Maximum'!T13 -> 4.39 | X13: ='3_Maximum'!T13 -> 5.33 | Y13: ='4_Maximum'!T13 -> 3.92 | Z13: ='1_Maximum'!S13 -> 0.1 | AA13: ='2_Maximum'!S13 -> 0.11 | AB13: ='3_Maximum'!S13 -> 0.1 | AC13: ='4_Maximum'!S13 -> 0.1 | AD13: 399 | AE13: 399 | AF13: 399 | AG13: 399
A14: =Q14 -> 60.11 | B14: =Z14 -> 0.1 | C14: =AA14 -> 0.1 | D14: =AB14 -> 0.1 | E14: =AC14 -> 0.1 | F14: 0.2 | G14: 0 | Q14: ='1_Maximum'!Q14 -> 60.11 | R14: ='1_Maximum'!R14 -> 1274.341 | S14: ='2_Maximum'!R14 -> 1294.31 | T14: ='3_Maximum'!R14 -> 1314.902 | U14: ='4_Maximum'!R14 -> 1334.308 | V14: ='1_Maximum'!T14 -> 4.75 | W14: ='2_Maximum'!T14 -> 4.52 | X14: ='3_Maximum'!T14 -> 5.43 | Y14: ='4_Maximum'!T14 -> 3.93 | Z14: ='1_Maximum'!S14 -> 0.1 | AA14: ='2_Maximum'!S14 -> 0.1 | AB14: ='3_Maximum'!S14 -> 0.1 | AC14: ='4_Maximum'!S14 -> 0.1 | AD14: 399 | AE14: 399 | AF14: 399 | AG14: 399
... A91: =Q91 -> 0 | B91: =Z91 -> 0 | C91: =AA91 -> 0 | D91: =AB91 -> 0 | E91: =AC91 -> 0 | F91: 0.2 | G91: 0 | Q91: ='1_Maximum'!Q91 -> 0 | R91: ='1_Maximum'!R91 -> 0 | S91: ='2_Maximum'!R91 -> 0 | T91: ='3_Maximum'!R91 -> 0 | U91: ='4_Maximum'!R91 -> 0 | V91: ='1_Maximum'!T91 -> 0 | W91: ='2_Maximum'!T91 -> 0 | X91: ='3_Maximum'!T91 -> 0 | Y91: ='4_Maximum'!T91 -> 0 | Z91: ='1_Maximum'!S91 -> 0 | AA91: ='2_Maximum'!S91 -> 0 | AB91: ='3_Maximum'!S91 -> 0 | AC91: ='4_Maximum'!S91 -> 0 | AD91: 399 | AE91: 399 | AF91: 399 | AG91: 399

Sheet 1_Operational
A1: TESTNUMBER | B1: WO | C1: TESTSN | D1: OPERATION | E1: PN | F1: EQUPMENT | G1: FIXTUREID | H1: TESTRESULT | I1: TESTOP | J1: TESTDATE | K1: TESTREASON | L1: TEST_STATUS | M1: CHNumber | N1: CH_Pass_Fail | O1: FailureCodeID | P1: Times | Q1: Case_Temp | R1: Wavelength | S1: dW/dT | T1: TXP | U1: Peak_WL_Jump_Max | V1: Peak_WL_Jump_Avg | W1: Peak_WL_Jump_Min | X1: CH1_DDMI_Bias | Y1: CH2_DDMI_Bias | Z1: CH3_DDMI_Bias | AA1: CH4_DDMI_Bias | AB1: CH5_DDMI_Bias | AC1: CH6_DDMI_Bias | AD1: CH7_DDMI_Bias | AE1: CH8_DDMI_Bias
A2: A2026061803031334877 | B2: 220029640 | C2: P305261700035 | D2: MODE HOPPING | E2: 400454000062 | F2: T157100002057_3 | G2: T157100002057_3 | H2: Pass | I2: TW82699 | J2: 2026/06/18 03:03:13 | L2: 0 | M2: 1_Operational | N2: Pass | O2: 0 | P2: 40 | Q2: -0.21 | R2: 1267.809 | S2: 0.08 | T2: 1.4 | U2: 0.17 | V2: 0.09 | W2: 0.06 | X2: 105 | Y2: 87 | Z2: 124 | AA2: 140 | AB2: 105 | AC2: 87 | AD2: 124 | AE2: 140
A3: A2026061803031334877 | B3: 220029640 | C3: P305261700035 | D3: MODE HOPPING | E3: 400454000062 | F3: T157100002057_3 | G3: T157100002057_3 | H3: Pass | I3: TW82699 | J3: 2026/06/18 03:03:13 | L3: 0 | M3: 1_Operational | N3: Pass | O3: 0 | P3: 45 | Q3: 0.75 | R3: 1267.892 | S3: 0.09 | T3: 1.29 | U3: 0.17 | V3: 0.09 | W3: 0.06 | X3: 105 | Y3: 87 | Z3: 124 | AA3: 140 | AB3: 105 | AC3: 87 | AD3: 124 | AE3: 140
A4: A2026061803031334877 | B4: 220029640 | C4: P305261700035 | D4: MODE HOPPING | E4: 400454000062 | F4: T157100002057_3 | G4: T157100002057_3 | H4: Pass | I4: TW82699 | J4: 2026/06/18 03:03:13 | L4: 0 | M4: 1_Operational | N4: Pass | O4: 0 | P4: 50 | Q4: 1.76 | R4: 1267.976 | S4: 0.08 | T4: 1.31 | U4: 0.17 | V4: 0.09 | W4: 0.06 | X4: 105 | Y4: 87 | Z4: 125 | AA4: 140 | AB4: 105 | AC4: 87 | AD4: 125 | AE4: 140
A5: A2026061803031334877 | B5: 220029640 | C5: P305261700035 | D5: MODE HOPPING | E5: 400454000062 | F5: T157100002057_3 | G5: T157100002057_3 | H5: Pass | I5: TW82699 | J5: 2026/06/18 03:03:13 | L5: 0 | M5: 1_Operational | N5: Pass | O5: 0 | P5: 55 | Q5: 2.7 | R5: 1268.061 | S5: 0.09 | T5: 1.36 | U5: 0.17 | V5: 0.09 | W5: 0.06 | X5: 105 | Y5: 88 | Z5: 126 | AA5: 140 | AB5: 105 | AC5: 88 | AD5: 126 | AE5: 140
A6: A2026061803031334877 | B6: 220029640 | C6: P305261700035 | D6: MODE HOPPING | E6: 400454000062 | F6: T157100002057_3 | G6: T157100002057_3 | H6: Pass | I6: TW82699 | J6: 2026/06/18 03:03:13 | L6: 0 | M6: 1_Operational | N6: Pass | O6: 0 | P6: 60 | Q6: 3.69 | R6: 1268.148 | S6: 0.09 | T6: 1.41 | U6: 0.17 | V6: 0.09 | W6: 0.06 | X6: 105 | Y6: 88 | Z6: 127 | AA6: 140 | AB6: 105 | AC6: 88 | AD6: 127 | AE6: 140
A7: A2026061803031334877 | B7: 220029640 | C7: P305261700035 | D7: MODE HOPPING | E7: 400454000062 | F7: T157100002057_3 | G7: T157100002057_3 | H7: Pass | I7: TW82699 | J7: 2026/06/18 03:03:13 | L7: 0 | M7: 1_Operational | N7: Pass | O7: 0 | P7: 65 | Q7: 4.67 | R7: 1268.233 | S7: 0.09 | T7: 1.35 | U7: 0.17 | V7: 0.09 | W7: 0.06 | X7: 105 | Y7: 88 | Z7: 127 | AA7: 140 | AB7: 105 | AC7: 88 | AD7: 127 | AE7: 140
A8: A2026061803031334877 | B8: 220029640 | C8: P305261700035 | D8: MODE HOPPING | E8: 400454000062 | F8: T157100002057_3 | G8: T157100002057_3 | H8: Pass | I8: TW82699 | J8: 2026/06/18 03:03:13 | L8: 0 | M8: 1_Operational | N8: Pass | O8: 0 | P8: 70 | Q8: 5.61 | R8: 1268.316 | S8: 0.09 | T8: 1.38 | U8: 0.17 | V8: 0.09 | W8: 0.06 | X8: 105 | Y8: 88 | Z8: 128 | AA8: 140 | AB8: 105 | AC8: 88 | AD8: 128 | AE8: 140
A9: A2026061803031334877 | B9: 220029640 | C9: P305261700035 | D9: MODE HOPPING | E9: 400454000062 | F9: T157100002057_3 | G9: T157100002057_3 | H9: Pass | I9: TW82699 | J9: 2026/06/18 03:03:13 | L9: 0 | M9: 1_Operational | N9: Pass | O9: 0 | P9: 75 | Q9: 6.5 | R9: 1268.398 | S9: 0.09 | T9: 1.36 | U9: 0.17 | V9: 0.09 | W9: 0.06 | X9: 105 | Y9: 88 | Z9: 129 | AA9: 140 | AB9: 105 | AC9: 88 | AD9: 129 | AE9: 140
A10: A2026061803031334877 | B10: 220029640 | C10: P305261700035 | D10: MODE HOPPING | E10: 400454000062 | F10: T157100002057_3 | G10: T157100002057_3 | H10: Pass | I10: TW82699 | J10: 2026/06/18 03:03:13 | L10: 0 | M10: 1_Operational | N10: Pass | O10: 0 | P10: 80 | Q10: 7.41 | R10: 1268.48 | S10: 0.09 | T10: 1.36 | U10: 0.17 | V10: 0.09 | W10: 0.06 | X10: 105 | Y10: 89 | Z10: 129 | AA10: 140 | AB10: 105 | AC10: 89 | AD10: 129 | AE10: 140
A11: A2026061803031334877 | B11: 220029640 | C11: P305261700035 | D11: MODE HOPPING | E11: 400454000062 | F11: T157100002057_3 | G11: T157100002057_3 | H11: Pass | I11: TW82699 | J11: 2026/06/18 03:03:13 | L11: 0 | M11: 1_Operational | N11: Pass | O11: 0 | P11: 85 | Q11: 8.3 | R11: 1268.559 | S11: 0.09 | T11: 1.35 | U11: 0.17 | V11: 0.09 | W11: 0.06 | X11: 105 | Y11: 89 | Z11: 130 | AA11: 141 | AB11: 105 | AC11: 89 | AD11: 130 | AE11: 141
A12: A2026061803031334877 | B12: 220029640 | C12: P305261700035 | D12: MODE HOPPING | E12: 400454000062 | F12: T157100002057_3 | G12: T157100002057_3 | H12: Pass | I12: TW82699 | J12: 2026/06/18 03:03:13 | L12: 0 | M12: 1_Operational | N12: Pass | O12: 0 | P12: 90 | Q12: 9.17 | R12: 1268.64 | S12: 0.09 | T12: 1.33 | U12: 0.17 | V12: 0.09 | W12: 0.06 | X12: 105 | Y12: 89 | Z12: 131 | AA12: 141 | AB12: 105 | AC12: 89 | AD12: 131 | AE12: 141
A13: A2026061803031334877 | B13: 220029640 | C13: P305261700035 | D13: MODE HOPPING | E13: 400454000062 | F13: T157100002057_3 | G13: T157100002057_3 | H13: Pass | I13: TW82699 | J13: 2026/06/18 03:03:13 | L13: 0 | M13: 1_Operational | N13: Pass | O13: 0 | P13: 95 | Q13: 10.05 | R13: 1268.718 | S13: 0.09 | T13: 1.32 | U13: 0.17 | V13: 0.09 | W13: 0.06 | X13: 105 | Y13: 90 | Z13: 132 | AA13: 141 | AB13: 105 | AC13: 90 | AD13: 132 | AE13: 141
... A84: A2026061803031334877 | B84: 220029640 | C84: P305261700035 | D84: MODE HOPPING | E84: 400454000062 | F84: T157100002057_3 | G84: T157100002057_3 | H84: Pass | I84: TW82699 | J84: 2026/06/18 03:03:13 | L84: 0 | M84: 1_Operational | N84: Pass | O84: 0 | P84: 450 | Q84: 70.11 | R84: 1274.391 | S84: 0.11 | T84: 1.06 | U84: 0.17 | V84: 0.09 | W84: 0.06 | X84: 195 | Y84: 173 | Z84: 214 | AA84: 213 | AB84: 195 | AC84: 173 | AD84: 214 | AE84: 213

Sheet 2_Operational
A1: TESTNUMBER | B1: WO | C1: TESTSN | D1: OPERATION | E1: PN | F1: EQUPMENT | G1: FIXTUREID | H1: TESTRESULT | I1: TESTOP | J1: TESTDATE | K1: TESTREASON | L1: TEST_STATUS | M1: CHNumber | N1: CH_Pass_Fail | O1: FailureCodeID | P1: Times | Q1: Case_Temp | R1: Wavelength | S1: dW/dT | T1: TXP | U1: Peak_WL_Jump_Max | V1: Peak_WL_Jump_Avg | W1: Peak_WL_Jump_Min | X1: CH1_DDMI_Bias | Y1: CH2_DDMI_Bias | Z1: CH3_DDMI_Bias | AA1: CH4_DDMI_Bias | AB1: CH5_DDMI_Bias | AC1: CH6_DDMI_Bias | AD1: CH7_DDMI_Bias | AE1: CH8_DDMI_Bias
A2: A2026061803031334877 | B2: 220029640 | C2: P305261700035 | D2: MODE HOPPING | E2: 400454000062 | F2: T157100002057_3 | G2: T157100002057_3 | H2: Pass | I2: TW82699 | J2: 2026/06/18 03:03:13 | L2: 0 | M2: 2_Operational | N2: Pass | O2: 0 | P2: 40 | Q2: -0.21 | R2: 1287.61 | S2: 0.08 | T2: 0.9 | U2: 0.18 | V2: 0.09 | W2: 0.06 | X2: 105 | Y2: 87 | Z2: 124 | AA2: 140 | AB2: 105 | AC2: 87 | AD2: 124 | AE2: 140
A3: A2026061803031334877 | B3: 220029640 | C3: P305261700035 | D3: MODE HOPPING | E3: 400454000062 | F3: T157100002057_3 | G3: T157100002057_3 | H3: Pass | I3: TW82699 | J3: 2026/06/18 03:03:13 | L3: 0 | M3: 2_Operational | N3: Pass | O3: 0 | P3: 45 | Q3: 0.75 | R3: 1287.694 | S3: 0.09 | T3: 0.86 | U3: 0.18 | V3: 0.09 | W3: 0.06 | X3: 105 | Y3: 87 | Z3: 124 | AA3: 140 | AB3: 105 | AC3: 87 | AD3: 124 | AE3: 140
A4: A2026061803031334877 | B4: 220029640 | C4: P305261700035 | D4: MODE HOPPING | E4: 400454000062 | F4: T157100002057_3 | G4: T157100002057_3 | H4: Pass | I4: TW82699 | J4: 2026/06/18 03:03:13 | L4: 0 | M4: 2_Operational | N4: Pass | O4: 0 | P4: 50 | Q4: 1.76 | R4: 1287.78 | S4: 0.09 | T4: 0.89 | U4: 0.18 | V4: 0.09 | W4: 0.06 | X4: 105 | Y4: 87 | Z4: 125 | AA4: 140 | AB4: 105 | AC4: 87 | AD4: 125 | AE4: 140
A5: A2026061803031334877 | B5: 220029640 | C5: P305261700035 | D5: MODE HOPPING | E5: 400454000062 | F5: T157100002057_3 | G5: T157100002057_3 | H5: Pass | I5: TW82699 | J5: 2026/06/18 03:03:13 | L5: 0 | M5: 2_Operational | N5: Pass | O5: 0 | P5: 55 | Q5: 2.7 | R5: 1287.868 | S5: 0.09 | T5: 0.94 | U5: 0.18 | V5: 0.09 | W5: 0.06 | X5: 105 | Y5: 88 | Z5: 126 | AA5: 140 | AB5: 105 | AC5: 88 | AD5: 126 | AE5: 140
A6: A2026061803031334877 | B6: 220029640 | C6: P305261700035 | D6: MODE HOPPING | E6: 400454000062 | F6: T157100002057_3 | G6: T157100002057_3 | H6: Pass | I6: TW82699 | J6: 2026/06/18 03:03:13 | L6: 0 | M6: 2_Operational | N6: Pass | O6: 0 | P6: 60 | Q6: 3.69 | R6: 1287.957 | S6: 0.09 | T6: 0.96 | U6: 0.18 | V6: 0.09 | W6: 0.06 | X6: 105 | Y6: 88 | Z6: 127 | AA6: 140 | AB6: 105 | AC6: 88 | AD6: 127 | AE6: 140
A7: A2026061803031334877 | B7: 220029640 | C7: P305261700035 | D7: MODE HOPPING | E7: 400454000062 | F7: T157100002057_3 | G7: T157100002057_3 | H7: Pass | I7: TW82699 | J7: 2026/06/18 03:03:13 | L7: 0 | M7: 2_Operational | N7: Pass | O7: 0 | P7: 65 | Q7: 4.67 | R7: 1288.044 | S7: 0.09 | T7: 1.02 | U7: 0.18 | V7: 0.09 | W7: 0.06 | X7: 105 | Y7: 88 | Z7: 127 | AA7: 140 | AB7: 105 | AC7: 88 | AD7: 127 | AE7: 140
A8: A2026061803031334877 | B8: 220029640 | C8: P305261700035 | D8: MODE HOPPING | E8: 400454000062 | F8: T157100002057_3 | G8: T157100002057_3 | H8: Pass | I8: TW82699 | J8: 2026/06/18 03:03:13 | L8: 0 | M8: 2_Operational | N8: Pass | O8: 0 | P8: 70 | Q8: 5.61 | R8: 1288.13 | S8: 0.09 | T8: 1.03 | U8: 0.18 | V8: 0.09 | W8: 0.06 | X8: 105 | Y8: 88 | Z8: 128 | AA8: 140 | AB8: 105 | AC8: 88 | AD8: 128 | AE8: 140
A9: A2026061803031334877 | B9: 220029640 | C9: P305261700035 | D9: MODE HOPPING | E9: 400454000062 | F9: T157100002057_3 | G9: T157100002057_3 | H9: Pass | I9: TW82699 | J9: 2026/06/18 03:03:13 | L9: 0 | M9: 2_Operational | N9: Pass | O9: 0 | P9: 75 | Q9: 6.5 | R9: 1288.214 | S9: 0.09 | T9: 1.01 | U9: 0.18 | V9: 0.09 | W9: 0.06 | X9: 105 | Y9: 88 | Z9: 129 | AA9: 140 | AB9: 105 | AC9: 88 | AD9: 129 | AE9: 140
A10: A2026061803031334877 | B10: 220029640 | C10: P305261700035 | D10: MODE HOPPING | E10: 400454000062 | F10: T157100002057_3 | G10: T157100002057_3 | H10: Pass | I10: TW82699 | J10: 2026/06/18 03:03:13 | L10: 0 | M10: 2_Operational | N10: Pass | O10: 0 | P10: 80 | Q10: 7.41 | R10: 1288.298 | S10: 0.09 | T10: 1.04 | U10: 0.18 | V10: 0.09 | W10: 0.06 | X10: 105 | Y10: 89 | Z10: 129 | AA10: 140 | AB10: 105 | AC10: 89 | AD10: 129 | AE10: 140
A11: A2026061803031334877 | B11: 220029640 | C11: P305261700035 | D11: MODE HOPPING | E11: 400454000062 | F11: T157100002057_3 | G11: T157100002057_3 | H11: Pass | I11: TW82699 | J11: 2026/06/18 03:03:13 | L11: 0 | M11: 2_Operational | N11: Pass | O11: 0 | P11: 85 | Q11: 8.3 | R11: 1288.379 | S11: 0.09 | T11: 1.04 | U11: 0.18 | V11: 0.09 | W11: 0.06 | X11: 105 | Y11: 89 | Z11: 130 | AA11: 141 | AB11: 105 | AC11: 89 | AD11: 130 | AE11: 141
A12: A2026061803031334877 | B12: 220029640 | C12: P305261700035 | D12: MODE HOPPING | E12: 400454000062 | F12: T157100002057_3 | G12: T157100002057_3 | H12: Pass | I12: TW82699 | J12: 2026/06/18 03:03:13 | L12: 0 | M12: 2_Operational | N12: Pass | O12: 0 | P12: 90 | Q12: 9.17 | R12: 1288.461 | S12: 0.09 | T12: 1.06 | U12: 0.18 | V12: 0.09 | W12: 0.06 | X12: 105 | Y12: 89 | Z12: 131 | AA12: 141 | AB12: 105 | AC12: 89 | AD12: 131 | AE12: 141
A13: A2026061803031334877 | B13: 220029640 | C13: P305261700035 | D13: MODE HOPPING | E13: 400454000062 | F13: T157100002057_3 | G13: T157100002057_3 | H13: Pass | I13: TW82699 | J13: 2026/06/18 03:03:13 | L13: 0 | M13: 2_Operational | N13: Pass | O13: 0 | P13: 95 | Q13: 10.05 | R13: 1288.54 | S13: 0.09 | T13: 1.08 | U13: 0.18 | V13: 0.09 | W13: 0.06 | X13: 105 | Y13: 90 | Z13: 132 | AA13: 141 | AB13: 105 | AC13: 90 | AD13: 132 | AE13: 141
... A84: A2026061803031334877 | B84: 220029640 | C84: P305261700035 | D84: MODE HOPPING | E84: 400454000062 | F84: T157100002057_3 | G84: T157100002057_3 | H84: Pass | I84: TW82699 | J84: 2026/06/18 03:03:13 | L84: 0 | M84: 2_Operational | N84: Pass | O84: 0 | P84: 450 | Q84: 70.11 | R84: 1294.266 | S84: 0.11 | T84: 0.82 | U84: 0.18 | V84: 0.09 | W84: 0.06 | X84: 195 | Y84: 173 | Z84: 214 | AA84: 213 | AB84: 195 | AC84: 173 | AD84: 214 | AE84: 213

Sheet 3_Operational
A1: TESTNUMBER | B1: WO | C1: TESTSN | D1: OPERATION | E1: PN | F1: EQUPMENT | G1: FIXTUREID | H1: TESTRESULT | I1: TESTOP | J1: TESTDATE | K1: TESTREASON | L1: TEST_STATUS | M1: CHNumber | N1: CH_Pass_Fail | O1: FailureCodeID | P1: Times | Q1: Case_Temp | R1: Wavelength | S1: dW/dT | T1: TXP | U1: Peak_WL_Jump_Max | V1: Peak_WL_Jump_Avg | W1: Peak_WL_Jump_Min | X1: CH1_DDMI_Bias | Y1: CH2_DDMI_Bias | Z1: CH3_DDMI_Bias | AA1: CH4_DDMI_Bias | AB1: CH5_DDMI_Bias | AC1: CH6_DDMI_Bias | AD1: CH7_DDMI_Bias | AE1: CH8_DDMI_Bias
A2: A2026061803031334877 | B2: 220029640 | C2: P305261700035 | D2: MODE HOPPING | E2: 400454000062 | F2: T157100002057_3 | G2: T157100002057_3 | H2: Pass | I2: TW82699 | J2: 2026/06/18 03:03:13 | L2: 0 | M2: 3_Operational | N2: Pass | O2: 0 | P2: 40 | Q2: -0.21 | R2: 1308.322 | S2: 0.08 | T2: 2.49 | U2: 0.17 | V2: 0.09 | W2: 0.06 | X2: 105 | Y2: 87 | Z2: 124 | AA2: 140 | AB2: 105 | AC2: 87 | AD2: 124 | AE2: 140
A3: A2026061803031334877 | B3: 220029640 | C3: P305261700035 | D3: MODE HOPPING | E3: 400454000062 | F3: T157100002057_3 | G3: T157100002057_3 | H3: Pass | I3: TW82699 | J3: 2026/06/18 03:03:13 | L3: 0 | M3: 3_Operational | N3: Pass | O3: 0 | P3: 45 | Q3: 0.75 | R3: 1308.407 | S3: 0.09 | T3: 2.49 | U3: 0.17 | V3: 0.09 | W3: 0.06 | X3: 105 | Y3: 87 | Z3: 124 | AA3: 140 | AB3: 105 | AC3: 87 | AD3: 124 | AE3: 140
A4: A2026061803031334877 | B4: 220029640 | C4: P305261700035 | D4: MODE HOPPING | E4: 400454000062 | F4: T157100002057_3 | G4: T157100002057_3 | H4: Pass | I4: TW82699 | J4: 2026/06/18 03:03:13 | L4: 0 | M4: 3_Operational | N4: Pass | O4: 0 | P4: 50 | Q4: 1.76 | R4: 1308.495 | S4: 0.09 | T4: 2.41 | U4: 0.17 | V4: 0.09 | W4: 0.06 | X4: 105 | Y4: 87 | Z4: 125 | AA4: 140 | AB4: 105 | AC4: 87 | AD4: 125 | AE4: 140
A5: A2026061803031334877 | B5: 220029640 | C5: P305261700035 | D5: MODE HOPPING | E5: 400454000062 | F5: T157100002057_3 | G5: T157100002057_3 | H5: Pass | I5: TW82699 | J5: 2026/06/18 03:03:13 | L5: 0 | M5: 3_Operational | N5: Pass | O5: 0 | P5: 55 | Q5: 2.7 | R5: 1308.583 | S5: 0.09 | T5: 2.46 | U5: 0.17 | V5: 0.09 | W5: 0.06 | X5: 105 | Y5: 88 | Z5: 126 | AA5: 140 | AB5: 105 | AC5: 88 | AD5: 126 | AE5: 140
A6: A2026061803031334877 | B6: 220029640 | C6: P305261700035 | D6: MODE HOPPING | E6: 400454000062 | F6: T157100002057_3 | G6: T157100002057_3 | H6: Pass | I6: TW82699 | J6: 2026/06/18 03:03:13 | L6: 0 | M6: 3_Operational | N6: Pass | O6: 0 | P6: 60 | Q6: 3.69 | R6: 1308.671 | S6: 0.09 | T6: 2.48 | U6: 0.17 | V6: 0.09 | W6: 0.06 | X6: 105 | Y6: 88 | Z6: 127 | AA6: 140 | AB6: 105 | AC6: 88 | AD6: 127 | AE6: 140
A7: A2026061803031334877 | B7: 220029640 | C7: P305261700035 | D7: MODE HOPPING | E7: 400454000062 | F7: T157100002057_3 | G7: T157100002057_3 | H7: Pass | I7: TW82699 | J7: 2026/06/18 03:03:13 | L7: 0 | M7: 3_Operational | N7: Pass | O7: 0 | P7: 65 | Q7: 4.67 | R7: 1308.758 | S7: 0.09 | T7: 2.48 | U7: 0.17 | V7: 0.09 | W7: 0.06 | X7: 105 | Y7: 88 | Z7: 127 | AA7: 140 | AB7: 105 | AC7: 88 | AD7: 127 | AE7: 140
A8: A2026061803031334877 | B8: 220029640 | C8: P305261700035 | D8: MODE HOPPING | E8: 400454000062 | F8: T157100002057_3 | G8: T157100002057_3 | H8: Pass | I8: TW82699 | J8: 2026/06/18 03:03:13 | L8: 0 | M8: 3_Operational | N8: Pass | O8: 0 | P8: 70 | Q8: 5.61 | R8: 1308.842 | S8: 0.09 | T8: 2.45 | U8: 0.17 | V8: 0.09 | W8: 0.06 | X8: 105 | Y8: 88 | Z8: 128 | AA8: 140 | AB8: 105 | AC8: 88 | AD8: 128 | AE8: 140
A9: A2026061803031334877 | B9: 220029640 | C9: P305261700035 | D9: MODE HOPPING | E9: 400454000062 | F9: T157100002057_3 | G9: T157100002057_3 | H9: Pass | I9: TW82699 | J9: 2026/06/18 03:03:13 | L9: 0 | M9: 3_Operational | N9: Pass | O9: 0 | P9: 75 | Q9: 6.5 | R9: 1308.925 | S9: 0.09 | T9: 2.46 | U9: 0.17 | V9: 0.09 | W9: 0.06 | X9: 105 | Y9: 88 | Z9: 129 | AA9: 140 | AB9: 105 | AC9: 88 | AD9: 129 | AE9: 140
A10: A2026061803031334877 | B10: 220029640 | C10: P305261700035 | D10: MODE HOPPING | E10: 400454000062 | F10: T157100002057_3 | G10: T157100002057_3 | H10: Pass | I10: TW82699 | J10: 2026/06/18 03:03:13 | L10: 0 | M10: 3_Operational | N10: Pass | O10: 0 | P10: 80 | Q10: 7.41 | R10: 1309.008 | S10: 0.09 | T10: 2.49 | U10: 0.17 | V10: 0.09 | W10: 0.06 | X10: 105 | Y10: 89 | Z10: 129 | AA10: 140 | AB10: 105 | AC10: 89 | AD10: 129 | AE10: 140
A11: A2026061803031334877 | B11: 220029640 | C11: P305261700035 | D11: MODE HOPPING | E11: 400454000062 | F11: T157100002057_3 | G11: T157100002057_3 | H11: Pass | I11: TW82699 | J11: 2026/06/18 03:03:13 | L11: 0 | M11: 3_Operational | N11: Pass | O11: 0 | P11: 85 | Q11: 8.3 | R11: 1309.088 | S11: 0.09 | T11: 2.48 | U11: 0.17 | V11: 0.09 | W11: 0.06 | X11: 105 | Y11: 89 | Z11: 130 | AA11: 141 | AB11: 105 | AC11: 89 | AD11: 130 | AE11: 141
A12: A2026061803031334877 | B12: 220029640 | C12: P305261700035 | D12: MODE HOPPING | E12: 400454000062 | F12: T157100002057_3 | G12: T157100002057_3 | H12: Pass | I12: TW82699 | J12: 2026/06/18 03:03:13 | L12: 0 | M12: 3_Operational | N12: Pass | O12: 0 | P12: 90 | Q12: 9.17 | R12: 1309.17 | S12: 0.09 | T12: 2.51 | U12: 0.17 | V12: 0.09 | W12: 0.06 | X12: 105 | Y12: 89 | Z12: 131 | AA12: 141 | AB12: 105 | AC12: 89 | AD12: 131 | AE12: 141
A13: A2026061803031334877 | B13: 220029640 | C13: P305261700035 | D13: MODE HOPPING | E13: 400454000062 | F13: T157100002057_3 | G13: T157100002057_3 | H13: Pass | I13: TW82699 | J13: 2026/06/18 03:03:13 | L13: 0 | M13: 3_Operational | N13: Pass | O13: 0 | P13: 95 | Q13: 10.05 | R13: 1309.249 | S13: 0.09 | T13: 2.51 | U13: 0.17 | V13: 0.09 | W13: 0.06 | X13: 105 | Y13: 90 | Z13: 132 | AA13: 141 | AB13: 105 | AC13: 90 | AD13: 132 | AE13: 141
... A84: A2026061803031334877 | B84: 220029640 | C84: P305261700035 | D84: MODE HOPPING | E84: 400454000062 | F84: T157100002057_3 | G84: T157100002057_3 | H84: Pass | I84: TW82699 | J84: 2026/06/18 03:03:13 | L84: 0 | M84: 3_Operational | N84: Pass | O84: 0 | P84: 450 | Q84: 70.11 | R84: 1314.936 | S84: 0.11 | T84: 2.29 | U84: 0.17 | V84: 0.09 | W84: 0.06 | X84: 195 | Y84: 173 | Z84: 214 | AA84: 213 | AB84: 195 | AC84: 173 | AD84: 214 | AE84: 213

Sheet 4_Operational
A1: TESTNUMBER | B1: WO | C1: TESTSN | D1: OPERATION | E1: PN | F1: EQUPMENT | G1: FIXTUREID | H1: TESTRESULT | I1: TESTOP | J1: TESTDATE | K1: TESTREASON | L1: TEST_STATUS | M1: CHNumber | N1: CH_Pass_Fail | O1: FailureCodeID | P1: Times | Q1: Case_Temp | R1: Wavelength | S1: dW/dT | T1: TXP | U1: Peak_WL_Jump_Max | V1: Peak_WL_Jump_Avg | W1: Peak_WL_Jump_Min | X1: CH1_DDMI_Bias | Y1: CH2_DDMI_Bias | Z1: CH3_DDMI_Bias | AA1: CH4_DDMI_Bias | AB1: CH5_DDMI_Bias | AC1: CH6_DDMI_Bias | AD1: CH7_DDMI_Bias | AE1: CH8_DDMI_Bias
A2: A2026061803031334877 | B2: 220029640 | C2: P305261700035 | D2: MODE HOPPING | E2: 400454000062 | F2: T157100002057_3 | G2: T157100002057_3 | H2: Pass | I2: TW82699 | J2: 2026/06/18 03:03:13 | L2: 0 | M2: 4_Operational | N2: Pass | O2: 0 | P2: 40 | Q2: -0.21 | R2: 1327.604 | S2: 0.08 | T2: 2.17 | U2: 0.18 | V2: 0.1 | W2: 0.06 | X2: 105 | Y2: 87 | Z2: 124 | AA2: 140 | AB2: 105 | AC2: 87 | AD2: 124 | AE2: 140
A3: A2026061803031334877 | B3: 220029640 | C3: P305261700035 | D3: MODE HOPPING | E3: 400454000062 | F3: T157100002057_3 | G3: T157100002057_3 | H3: Pass | I3: TW82699 | J3: 2026/06/18 03:03:13 | L3: 0 | M3: 4_Operational | N3: Pass | O3: 0 | P3: 45 | Q3: 0.75 | R3: 1327.69 | S3: 0.09 | T3: 2.11 | U3: 0.18 | V3: 0.1 | W3: 0.06 | X3: 105 | Y3: 87 | Z3: 124 | AA3: 140 | AB3: 105 | AC3: 87 | AD3: 124 | AE3: 140
A4: A2026061803031334877 | B4: 220029640 | C4: P305261700035 | D4: MODE HOPPING | E4: 400454000062 | F4: T157100002057_3 | G4: T157100002057_3 | H4: Pass | I4: TW82699 | J4: 2026/06/18 03:03:13 | L4: 0 | M4: 4_Operational | N4: Pass | O4: 0 | P4: 50 | Q4: 1.76 | R4: 1327.778 | S4: 0.09 | T4: 2.08 | U4: 0.18 | V4: 0.1 | W4: 0.06 | X4: 105 | Y4: 87 | Z4: 125 | AA4: 140 | AB4: 105 | AC4: 87 | AD4: 125 | AE4: 140
A5: A2026061803031334877 | B5: 220029640 | C5: P305261700035 | D5: MODE HOPPING | E5: 400454000062 | F5: T157100002057_3 | G5: T157100002057_3 | H5: Pass | I5: TW82699 | J5: 2026/06/18 03:03:13 | L5: 0 | M5: 4_Operational | N5: Pass | O5: 0 | P5: 55 | Q5: 2.7 | R5: 1327.866 | S5: 0.09 | T5: 2.09 | U5: 0.18 | V5: 0.1 | W5: 0.06 | X5: 105 | Y5: 88 | Z5: 126 | AA5: 140 | AB5: 105 | AC5: 88 | AD5: 126 | AE5: 140
A6: A2026061803031334877 | B6: 220029640 | C6: P305261700035 | D6: MODE HOPPING | E6: 400454000062 | F6: T157100002057_3 | G6: T157100002057_3 | H6: Pass | I6: TW82699 | J6: 2026/06/18 03:03:13 | L6: 0 | M6: 4_Operational | N6: Pass | O6: 0 | P6: 60 | Q6: 3.69 | R6: 1327.956 | S6: 0.09 | T6: 2.14 | U6: 0.18 | V6: 0.1 | W6: 0.06 | X6: 105 | Y6: 88 | Z6: 127 | AA6: 140 | AB6: 105 | AC6: 88 | AD6: 127 | AE6: 140
A7: A2026061803031334877 | B7: 220029640 | C7: P305261700035 | D7: MODE HOPPING | E7: 400454000062 | F7: T157100002057_3 | G7: T157100002057_3 | H7: Pass | I7: TW82699 | J7: 2026/06/18 03:03:13 | L7: 0 | M7: 4_Operational | N7: Pass | O7: 0 | P7: 65 | Q7: 4.67 | R7: 1328.045 | S7: 0.09 | T7: 2.09 | U7: 0.18 | V7: 0.1 | W7: 0.06 | X7: 105 | Y7: 88 | Z7: 127 | AA7: 140 | AB7: 105 | AC7: 88 | AD7: 127 | AE7: 140
A8: A2026061803031334877 | B8: 220029640 | C8: P305261700035 | D8: MODE HOPPING | E8: 400454000062 | F8: T157100002057_3 | G8: T157100002057_3 | H8: Pass | I8: TW82699 | J8: 2026/06/18 03:03:13 | L8: 0 | M8: 4_Operational | N8: Pass | O8: 0 | P8: 70 | Q8: 5.61 | R8: 1328.132 | S8: 0.09 | T8: 2.09 | U8: 0.18 | V8: 0.1 | W8: 0.06 | X8: 105 | Y8: 88 | Z8: 128 | AA8: 140 | AB8: 105 | AC8: 88 | AD8: 128 | AE8: 140
A9: A2026061803031334877 | B9: 220029640 | C9: P305261700035 | D9: MODE HOPPING | E9: 400454000062 | F9: T157100002057_3 | G9: T157100002057_3 | H9: Pass | I9: TW82699 | J9: 2026/06/18 03:03:13 | L9: 0 | M9: 4_Operational | N9: Pass | O9: 0 | P9: 75 | Q9: 6.5 | R9: 1328.218 | S9: 0.1 | T9: 2.07 | U9: 0.18 | V9: 0.1 | W9: 0.06 | X9: 105 | Y9: 88 | Z9: 129 | AA9: 140 | AB9: 105 | AC9: 88 | AD9: 129 | AE9: 140
A10: A2026061803031334877 | B10: 220029640 | C10: P305261700035 | D10: MODE HOPPING | E10: 400454000062 | F10: T157100002057_3 | G10: T157100002057_3 | H10: Pass | I10: TW82699 | J10: 2026/06/18 03:03:13 | L10: 0 | M10: 4_Operational | N10: Pass | O10: 0 | P10: 80 | Q10: 7.41 | R10: 1328.303 | S10: 0.09 | T10: 2.08 | U10: 0.18 | V10: 0.1 | W10: 0.06 | X10: 105 | Y10: 89 | Z10: 129 | AA10: 140 | AB10: 105 | AC10: 89 | AD10: 129 | AE10: 140
A11: A2026061803031334877 | B11: 220029640 | C11: P305261700035 | D11: MODE HOPPING | E11: 400454000062 | F11: T157100002057_3 | G11: T157100002057_3 | H11: Pass | I11: TW82699 | J11: 2026/06/18 03:03:13 | L11: 0 | M11: 4_Operational | N11: Pass | O11: 0 | P11: 85 | Q11: 8.3 | R11: 1328.388 | S11: 0.1 | T11: 2.13 | U11: 0.18 | V11: 0.1 | W11: 0.06 | X11: 105 | Y11: 89 | Z11: 130 | AA11: 141 | AB11: 105 | AC11: 89 | AD11: 130 | AE11: 141
A12: A2026061803031334877 | B12: 220029640 | C12: P305261700035 | D12: MODE HOPPING | E12: 400454000062 | F12: T157100002057_3 | G12: T157100002057_3 | H12: Pass | I12: TW82699 | J12: 2026/06/18 03:03:13 | L12: 0 | M12: 4_Operational | N12: Pass | O12: 0 | P12: 90 | Q12: 9.17 | R12: 1328.472 | S12: 0.1 | T12: 2.13 | U12: 0.18 | V12: 0.1 | W12: 0.06 | X12: 105 | Y12: 89 | Z12: 131 | AA12: 141 | AB12: 105 | AC12: 89 | AD12: 131 | AE12: 141
A13: A2026061803031334877 | B13: 220029640 | C13: P305261700035 | D13: MODE HOPPING | E13: 400454000062 | F13: T157100002057_3 | G13: T157100002057_3 | H13: Pass | I13: TW82699 | J13: 2026/06/18 03:03:13 | L13: 0 | M13: 4_Operational | N13: Pass | O13: 0 | P13: 95 | Q13: 10.05 | R13: 1328.553 | S13: 0.09 | T13: 2.07 | U13: 0.18 | V13: 0.1 | W13: 0.06 | X13: 105 | Y13: 90 | Z13: 132 | AA13: 141 | AB13: 105 | AC13: 90 | AD13: 132 | AE13: 141
... A84: A2026061803031334877 | B84: 220029640 | C84: P305261700035 | D84: MODE HOPPING | E84: 400454000062 | F84: T157100002057_3 | G84: T157100002057_3 | H84: Pass | I84: TW82699 | J84: 2026/06/18 03:03:13 | L84: 0 | M84: 4_Operational | N84: Pass | O84: 0 | P84: 450 | Q84: 70.11 | R84: 1334.331 | S84: 0.11 | T84: 1.67 | U84: 0.18 | V84: 0.1 | W84: 0.06 | X84: 195 | Y84: 173 | Z84: 214 | AA84: 213 | AB84: 195 | AC84: 173 | AD84: 214 | AE84: 213

Sheet 1_Maximum
A1: TESTNUMBER | B1: WO | C1: TESTSN | D1: OPERATION | E1: PN | F1: EQUPMENT | G1: FIXTUREID | H1: TESTRESULT | I1: TESTOP | J1: TESTDATE | K1: TESTREASON | L1: TEST_STATUS | M1: CHNumber | N1: CH_Pass_Fail | O1: FailureCodeID | P1: Times | Q1: Case_Temp | R1: Wavelength | S1: dW/dT | T1: TXP | U1: Peak_WL_Jump_Max | V1: Peak_WL_Jump_Avg | W1: Peak_WL_Jump_Min | X1: CH1_DDMI_Bias | Y1: CH2_DDMI_Bias | Z1: CH3_DDMI_Bias | AA1: CH4_DDMI_Bias | AB1: CH5_DDMI_Bias | AC1: CH6_DDMI_Bias | AD1: CH7_DDMI_Bias | AE1: CH8_DDMI_Bias
A2: A2026061803031334877 | B2: 220029640 | C2: P305261700035 | D2: MODE HOPPING | E2: 400454000062 | F2: T157100002057_3 | G2: T157100002057_3 | H2: Pass | I2: TW82699 | J2: 2026/06/18 03:03:13 | L2: 0 | M2: 1_Maximum | N2: Pass | O2: 0 | P2: 30 | Q2: 70.77 | R2: 1275.393 | S2: 0.1 | T2: 2.83 | U2: 0.11 | V2: 0.09 | W2: 0.07 | X2: 399 | Y2: 399 | Z2: 399 | AA2: 399 | AB2: 399 | AC2: 399 | AD2: 399 | AE2: 399
A3: A2026061803031334877 | B3: 220029640 | C3: P305261700035 | D3: MODE HOPPING | E3: 400454000062 | F3: T157100002057_3 | G3: T157100002057_3 | H3: Pass | I3: TW82699 | J3: 2026/06/18 03:03:13 | L3: 0 | M3: 1_Maximum | N3: Pass | O3: 0 | P3: 35 | Q3: 69.81 | R3: 1275.306 | S3: 0.09 | T3: 3.08 | U3: 0.11 | V3: 0.09 | W3: 0.07 | X3: 399 | Y3: 399 | Z3: 399 | AA3: 399 | AB3: 399 | AC3: 399 | AD3: 399 | AE3: 399
A4: A2026061803031334877 | B4: 220029640 | C4: P305261700035 | D4: MODE HOPPING | E4: 400454000062 | F4: T157100002057_3 | G4: T157100002057_3 | H4: Pass | I4: TW82699 | J4: 2026/06/18 03:03:13 | L4: 0 | M4: 1_Maximum | N4: Pass | O4: 0 | P4: 40 | Q4: 69 | R4: 1275.219 | S4: 0.11 | T4: 3.26 | U4: 0.11 | V4: 0.09 | W4: 0.07 | X4: 399 | Y4: 399 | Z4: 399 | AA4: 399 | AB4: 399 | AC4: 399 | AD4: 399 | AE4: 399
